Workbook

Sheet Diagram WBS
H2: Sistem Informasi Pemesanan dan Pengelolaan Toko Kue Lala Berbasis Web
C6: ='Kamus WBS'!A6&CHAR(10)&'Kamus WBS'!B6 -> 1 Manajemen Proyek | E6: ='Kamus WBS'!A9&CHAR(10)&'Kamus WBS'!B9 -> 2 Definisi Proyek | G6: ='Kamus WBS'!A14&CHAR(10)&'Kamus WBS'!B14 -> 3 Perencanaan | I6: ='Kamus WBS'!A19&CHAR(10)&'Kamus WBS'!B19 -> 4 Analisis Kebutuhan | K6: ='Kamus WBS'!A24&CHAR(10)&'Kamus WBS'!B24 -> 5 Desain Sistem | M6: ='Kamus WBS'!A29&CHAR(10)&'Kamus WBS'!B29 -> 6 Pemrograman | O6: ='Kamus WBS'!A33&CHAR(10)&'Kamus WBS'!B33 -> 7 Pengujian | Q6: ='Kamus WBS'!A37&CHAR(10)&'Kamus WBS'!B37 -> 8 Penerapan
C9: ='Kamus WBS'!A7&CHAR(10)&'Kamus WBS'!B7 -> 1.1 Rapat mingguan tim & klien | E9: ='Kamus WBS'!A10&CHAR(10)&'Kamus WBS'!B10 -> 2.1 Identifikasi klien & masalah | G9: ='Kamus WBS'!A15&CHAR(10)&'Kamus WBS'!B15 -> 3.1 Proses bisnis & gambaran sistem | I9: ='Kamus WBS'!A20&CHAR(10)&'Kamus WBS'!B20 -> 4.1 Wawancara & observasi lanjutan | K9: ='Kamus WBS'!A25&CHAR(10)&'Kamus WBS'!B25 -> 5.1 Perancangan basis data (ERD) | M9: ='Kamus WBS'!A30&CHAR(10)&'Kamus WBS'!B30 -> 6.1 Sprint 1 – fitur dasar | O9: ='Kamus WBS'!A34&CHAR(10)&'Kamus WBS'!B34 -> 7.1 Pengujian modul & integrasi | Q9: ='Kamus WBS'!A38&CHAR(10)&'Kamus WBS'!B38 -> 8.1 Deploy final ke hosting klien
C12: ='Kamus WBS'!A8&CHAR(10)&'Kamus WBS'!B8 -> 1.2 Pemantauan jadwal & risiko | E12: ='Kamus WBS'!A11&CHAR(10)&'Kamus WBS'!B11 -> 2.2 Penentuan tujuan, lingkup & batasan | G12: ='Kamus WBS'!A16&CHAR(10)&'Kamus WBS'!B16 -> 3.2 Analisis kelayakan | I12: ='Kamus WBS'!A21&CHAR(10)&'Kamus WBS'!B21 -> 4.2 Kebutuhan fungsional & non-fungsional | K12: ='Kamus WBS'!A26&CHAR(10)&'Kamus WBS'!B26 -> 5.2 Arsitektur sistem & desain modul | M12: ='Kamus WBS'!A31&CHAR(10)&'Kamus WBS'!B31 -> 6.2 Sprint 2 – fitur lanjutan | O12: ='Kamus WBS'!A35&CHAR(10)&'Kamus WBS'!B35 -> 7.2 User Acceptance Test (UAT) | Q12: ='Kamus WBS'!A39&CHAR(10)&'Kamus WBS'!B39 -> 8.2 Pelatihan pengguna
E15: ='Kamus WBS'!A12&CHAR(10)&'Kamus WBS'!B12 -> 2.3 Alternatif solusi & metodologi | G15: ='Kamus WBS'!A17&CHAR(10)&'Kamus WBS'!B17 -> 3.3 WBS & Gantt Chart | I15: ='Kamus WBS'!A22&CHAR(10)&'Kamus WBS'!B22 -> 4.3 Prioritas MoSCoW & use case | K15: ='Kamus WBS'!A27&CHAR(10)&'Kamus WBS'!B27 -> 5.3 Desain antarmuka (wireframe) | M15: ='Kamus WBS'!A32&CHAR(10)&'Kamus WBS'!B32 -> 6.3 Sprint 3 – semua fitur lengkap | O15: ='Kamus WBS'!A36&CHAR(10)&'Kamus WBS'!B36 -> 7.3 Perbaikan bug & uji ulang | Q15: ='Kamus WBS'!A40&CHAR(10)&'Kamus WBS'!B40 -> 8.3 User manual & dokumen penerapan
E18: ='Kamus WBS'!A13&CHAR(10)&'Kamus WBS'!B13 -> 2.4 Penyusunan RD & persetujuan klien | G18: ='Kamus WBS'!A18&CHAR(10)&'Kamus WBS'!B18 -> 3.4 Dokumen Bagian II & presentasi | I18: ='Kamus WBS'!A23&CHAR(10)&'Kamus WBS'!B23 -> 4.4 Penyusunan & review SRS | K18: ='Kamus WBS'!A28&CHAR(10)&'Kamus WBS'!B28 -> 5.4 Penyusunan SDD | Q18: ='Kamus WBS'!A41&CHAR(10)&'Kamus WBS'!B41 -> 8.4 BAST & laporan akhir
A21: Diagram ini terhubung ke sheet Kamus WBS: perubahan kode atau nama paket kerja di sana otomatis tampil di sini.

Sheet Kamus WBS
A1: KAMUS WBS (WORK BREAKDOWN STRUCTURE)
A2: Sistem Informasi Pemesanan dan Pengelolaan Toko Kue Lala Berbasis Web · Kelompok 4 / 4KA22 · Dokumen 01 Bagian II, butir 5.2
A3: PIC ditulis berdasarkan peran pada Bagian I (PM = Project Manager, SA = System Analyst, SD = System Designer; satu anggota dapat memegang lebih dari satu peran). Durasi dalam hari kerja. Angka biru = input yang boleh diubah; Gantt Chart ikut menyesuaikan.
A5: Kode | B5: Paket Kerja | C5: Deliverable | D5: PIC (Peran) | E5: Durasi (hari kerja)
A6: 1 | B6: Manajemen Proyek | C6: Notulen, laporan status | D6: PM | E6: Sepanjang proyek
A7: 1.1 | B7: Rapat mingguan tim & klien | C7: Notulen rapat | D7: PM | E7: Sepanjang proyek
A8: 1.2 | B8: Pemantauan jadwal & risiko | C8: Gantt (realisasi), daftar risiko | D8: PM | E8: Sepanjang proyek
A9: 2 | B9: Definisi Proyek | C9: Requirement Document | D9: SA | E9: ='Gantt Chart'!D13 -> 10
A10: 2.1 | B10: Identifikasi klien & masalah | C10: Hasil wawancara, observasi, studi dokumen | D10: SA | E10: 3
A11: 2.2 | B11: Penentuan tujuan, lingkup & batasan | C11: Tujuan, ruang lingkup, batasan proyek | D11: SA | E11: 2
A12: 2.3 | B12: Alternatif solusi & metodologi | C12: Solusi dan metodologi terpilih | D12: SA | E12: 3
A13: 2.4 | B13: Penyusunan RD & persetujuan klien | C13: RD v1.0, lembar persetujuan klien | D13: PM | E13: 2
A14: 3 | B14: Perencanaan | C14: Dokumen 01 Bag. II, Gantt Chart | D14: PM | E14: ='Gantt Chart'!D18 -> 10
A15: 3.1 | B15: Proses bisnis & gambaran sistem | C15: Diagram As-Is/To-Be, gambaran sistem | D15: SA | E15: 3
A16: 3.2 | B16: Analisis kelayakan | C16: Analisis teknis, ekonomi, operasional | D16: SA | E16: 3
A17: 3.3 | B17: WBS & Gantt Chart | C17: Diagram WBS, kamus WBS, Gantt Chart | D17: PM | E17: 2
A18: 3.4 | B18: Dokumen Bagian II & presentasi | C18: Dokumen 01 Bag. II, bahan presentasi | D18: Tech. Writer | E18: 2
A19: 4 | B19: Analisis Kebutuhan | C19: SRS | D19: SA | E19: ='Gantt Chart'!D23 -> 10
A20: 4.1 | B20: Wawancara & observasi lanjutan | C20: Catatan kebutuhan rinci | D20: SA | E20: 2
A21: 4.2 | B21: Kebutuhan fungsional & non-fungsional | C21: Daftar kebutuhan terperinci | D21: SA | E21: 3
A22: 4.3 | B22: Prioritas MoSCoW & use case | C22: Tabel prioritas, use case diagram | D22: SA | E22: 3
A23: 4.4 | B23: Penyusunan & review SRS | C23: Dokumen SRS | D23: Tech. Writer | E23: 2
A24: 5 | B24: Desain Sistem | C24: SDD | D24: SD | E24: ='Gantt Chart'!D28 -> 10
A25: 5.1 | B25: Perancangan basis data (ERD) | C25: ERD, skema basis data MySQL | D25: SD | E25: 3
A26: 5.2 | B26: Arsitektur sistem & desain modul | C26: Arsitektur, desain modul | D26: SD | E26: 2
A27: 5.3 | B27: Desain antarmuka (wireframe) | C27: Wireframe desktop & HP | D27: SD | E27: 3
A28: 5.4 | B28: Penyusunan SDD | C28: Dokumen SDD | D28: SD | E28: 2
A29: 6 | B29: Pemrograman | C29: Aplikasi, dok. implementasi | D29: Programmer | E29: ='Gantt Chart'!D33 -> 15
A30: 6.1 | B30: Sprint 1 – fitur dasar | C30: Akun, katalog, produk (F-01, F-02, F-06); demo | D30: Programmer | E30: 5
A31: 6.2 | B31: Sprint 2 – fitur lanjutan | C31: Pemesanan, pembayaran, pesanan (F-03, F-04, F-05); demo | D31: Programmer | E31: 5
A32: 6.3 | B32: Sprint 3 – semua fitur lengkap | C32: Stok, penjualan toko, laporan (F-07 s.d. F-09); aplikasi lengkap, dok. implementasi, demo | D32: Programmer | E32: 5
A33: 7 | B33: Pengujian | C33: Skenario uji & UAT | D33: Tester | E33: ='Gantt Chart'!D37 -> 5
A34: 7.1 | B34: Pengujian modul & integrasi | C34: Skenario uji, hasil uji modul dan integrasi | D34: Tester | E34: 2
A35: 7.2 | B35: User Acceptance Test (UAT) | C35: Hasil UAT bersama klien | D35: Tester | E35: 2
A36: 7.3 | B36: Perbaikan bug & uji ulang | C36: Aplikasi bebas bug kritis | D36: Programmer | E36: 1
A37: 8 | B37: Penerapan | C37: User manual, BAST, laporan | D37: Tech. Writer | E37: ='Gantt Chart'!D41 -> 10
A38: 8.1 | B38: Deploy final ke hosting klien | C38: Aplikasi final di server produksi | D38: Programmer | E38: 2
A39: 8.2 | B39: Pelatihan pengguna | C39: Pelatihan 2 sesi (±2 jam) untuk pemilik dan staf | D39: PM | E39: 3
A40: 8.3 | B40: User manual & dokumen penerapan | C40: User manual, dokumen penerapan | D40: Tech. Writer | E40: 4
A41: 8.4 | B41: BAST & laporan akhir | C41: BAST bertanda tangan, laporan akhir | D41: Tech. Writer | E41: 4
...

Sheet Gantt Chart
A1: GANTT CHART PROYEK
A2: Sistem Informasi Pemesanan dan Pengelolaan Toko Kue Lala Berbasis Web · Kelompok 4 / 4KA22 · Dokumen 01 Bagian II, butir 6
B3: Tanggal mulai proyek (Senin, Minggu 1) | C3: 46300 | E3: ← input (kuning): ubah bila tanggal Minggu 1 berbeda
B4: Minggu UTS / UAS (tanpa pekerjaan) | C4: 11 | D4: 16
B5: baris bantu: hari kerja efektif per kolom (disembunyikan) | M5: =#REF! -> #REF! | N5: =#REF! -> #REF! | O5: =#REF! -> #REF! | P5: =#REF! -> #REF! | Q5: =#REF! -> #REF! | R5: =#REF! -> #REF! | S5: =#REF! -> #REF! | T5: =#REF! -> #REF! | ... CN5: =#REF! -> #REF!
B6: baris bantu: tanggal per kolom (disembunyikan) | M6: =#REF! -> #REF! | N6: =#REF! -> #REF! | O6: =#REF! -> #REF! | P6: =#REF! -> #REF! | Q6: =#REF! -> #REF! | R6: =#REF! -> #REF! | S6: =#REF! -> #REF! | T6: =#REF! -> #REF! | ... CN6: =#REF! -> #REF!
A7: Kode | B7: Paket Kerja / Tugas | C7: PIC | D7: Durasi (hari) | E7: Pendahulu | F7: Hari Mulai* | G7: Hari Selesai* | H7: Tgl Mulai | I7: Tgl Selesai | J7: Mg Mulai | K7: Mg Selesai | L7: Realisasi | M7: =IF(#REF!=1,IF(#REF!=$C$4,"UTS","UAS"),"Mg "&#REF!) -> #REF! | R7: =IF(#REF!=1,IF(#REF!=$C$4,"UTS","UAS"),"Mg "&#REF!) -> #REF! | W7: =IF(#REF!=1,IF(#REF!=$C$4,"UTS","UAS"),"Mg "&#REF!) -> #REF! | AB7: =IF(#REF!=1,IF(#REF!=$C$4,"UTS","UAS"),"Mg "&#REF!) -> #REF! | AG7: =IF(#REF!=1,IF(#REF!=$C$4,"UTS","UAS"),"Mg "&#REF!) -> #REF! | AL7: =IF(#REF!=1,IF(#REF!=$C$4,"UTS","UAS"),"Mg "&#REF!) -> #REF! | AQ7: =IF(#REF!=1,IF(#REF!=$C$4,"UTS","UAS"),"Mg "&#REF!) -> #REF! | AV7: =IF(#REF!=1,IF(#REF!=$C$4,"UTS","UAS"),"Mg "&#REF!) -> #REF! | BA7: =IF(#REF!=1,IF(#REF!=$C$4,"UTS","UAS"),"Mg "&#REF!) -> #REF! | BF7: =IF(#REF!=1,IF(#REF!=$C$4,"UTS","UAS"),"Mg "&#REF!) -> #REF! | BK7: =IF(#REF!=1,IF(#REF!=$C$4,"UTS","UAS"),"Mg "&#REF!) -> #REF! | BP7: =IF(#REF!=1,IF(#REF!=$C$4,"UTS","UAS"),"Mg "&#REF!) -> #REF! | BU7: =IF(#REF!=1,IF(#REF!=$C$4,"UTS","UAS"),"Mg "&#REF!) -> #REF! | BZ7: =IF(#REF!=1,IF(#REF!=$C$4,"UTS","UAS"),"Mg "&#REF!) -> #REF! | CE7: =IF(#REF!=1,IF(#REF!=$C$4,"UTS","UAS"),"Mg "&#REF!) -> #REF! | CJ7: =IF(#REF!=1,IF(#REF!=$C$4,"UTS","UAS"),"Mg "&#REF!) -> #REF!
M8: =#REF! -> #REF! | R8: =#REF! -> #REF! | W8: =#REF! -> #REF! | AB8: =#REF! -> #REF! | AG8: =#REF! -> #REF! | AL8: =#REF! -> #REF! | AQ8: =#REF! -> #REF! | AV8: =#REF! -> #REF! | BA8: =#REF! -> #REF! | BF8: =#REF! -> #REF! | BK8: =#REF! -> #REF! | BP8: =#REF! -> #REF! | BU8: =#REF! -> #REF! | BZ8: =#REF! -> #REF! | CE8: =#REF! -> #REF! | CJ8: =#REF! -> #REF!
M9: S | N9: S | O9: R | P9: K | Q9: J | R9: S | S9: S | T9: R | U9: K | V9: J | W9: S | X9: S | Y9: R | Z9: K | AA9: J | AB9: S | AC9: S | AD9: R | AE9: K | AF9: J | AG9: S | AH9: S | AI9: R | AJ9: K | AK9: J | AL9: S | AM9: S | AN9: R | AO9: K | AP9: J | AQ9: S | AR9: S | AS9: R | AT9: K | AU9: J | AV9: S | AW9: S | AX9: R | AY9: K | AZ9: J | BA9: S | BB9: S | BC9: R | BD9: K | BE9: J | BF9: S | BG9: S | BH9: R | BI9: K | BJ9: J | BK9: S | BL9: S | BM9: R | BN9: K | BO9: J | BP9: S | BQ9: S | BR9: R | BS9: K | BT9: J | BU9: S | BV9: S | BW9: R | BX9: K | BY9: J | BZ9: S | CA9: S | CB9: R | CC9: K | CD9: J | CE9: S | CF9: S | CG9: R | CH9: K | CI9: J | CJ9: S | CK9: S | CL9: R | CM9: K | CN9: J
A10: ='Kamus WBS'!A6 -> 1 | B10: ='Kamus WBS'!B6 -> Manajemen Proyek | C10: ='Kamus WBS'!D6 -> PM | D10: =G10-F10+1 -> 70 | E10: — | F10: =MIN(F11:F12) -> 1 | G10: =MAX(G11:G12) -> 70 | H10: =IFERROR(INDEX(#REF!,MATCH(F10,#REF!,0)),"—") -> — | I10: =IFERROR(INDEX(#REF!,MATCH(G10,#REF!,0)),"—") -> — | J10: =IFERROR(INDEX(#REF!,MATCH(F10,#REF!,0)),"—") -> — | K10: =IFERROR(INDEX(#REF!,MATCH(G10,#REF!,0)),"—") -> — | L10: =IF(COUNTIF(L11:L12,"✓ Selesai")=ROWS(L11:L12),"✓ Selesai",IF(COUNTIF(L11:L12,"Terlambat")>0,"Terlambat",IF(COUNTIF(L11:L12,"Revisi")>0,"Revisi","Belum"))) -> ✓ Selesai
A11: ='Kamus WBS'!A7 -> 1.1 | B11: ='Kamus WBS'!B7 -> Rapat mingguan tim & klien | C11: ='Kamus WBS'!D7 -> PM | D11: =G11-F11+1 -> 70 | E11: — | F11: =IF(OR(E11="",E11="—"),1,INDEX($G$10:$G$45,MATCH(E11,$A$10:$A$45,0))+1) -> 1 | G11: =MAX(G13,G18,G23,G28,G33,G37,G41) -> 70 | H11: =IFERROR(INDEX(#REF!,MATCH(F11,#REF!,0)),"—") -> — | I11: =IFERROR(INDEX(#REF!,MATCH(G11,#REF!,0)),"—") -> — | J11: =IFERROR(INDEX(#REF!,MATCH(F11,#REF!,0)),"—") -> — | K11: =IFERROR(INDEX(#REF!,MATCH(G11,#REF!,0)),"—") -> — | L11: ✓ Selesai
A12: ='Kamus WBS'!A8 -> 1.2 | B12: ='Kamus WBS'!B8 -> Pemantauan jadwal & risiko | C12: ='Kamus WBS'!D8 -> PM | D12: =G12-F12+1 -> 70 | E12: — | F12: =IF(OR(E12="",E12="—"),1,INDEX($G$10:$G$45,MATCH(E12,$A$10:$A$45,0))+1) -> 1 | G12: =MAX(G13,G18,G23,G28,G33,G37,G41) -> 70 | H12: =IFERROR(INDEX(#REF!,MATCH(F12,#REF!,0)),"—") -> — | I12: =IFERROR(INDEX(#REF!,MATCH(G12,#REF!,0)),"—") -> — | J12: =IFERROR(INDEX(#REF!,MATCH(F12,#REF!,0)),"—") -> — | K12: =IFERROR(INDEX(#REF!,MATCH(G12,#REF!,0)),"—") -> — | L12: ✓ Selesai
A13: ='Kamus WBS'!A9 -> 2 | B13: ='Kamus WBS'!B9 -> Definisi Proyek | C13: ='Kamus WBS'!D9 -> SA | D13: =G13-F13+1 -> 10 | E13: — | F13: =MIN(F14:F17) -> 1 | G13: =MAX(G14:G17) -> 10 | H13: =IFERROR(INDEX(#REF!,MATCH(F13,#REF!,0)),"—") -> — | I13: =IFERROR(INDEX(#REF!,MATCH(G13,#REF!,0)),"—") -> — | J13: =IFERROR(INDEX(#REF!,MATCH(F13,#REF!,0)),"—") -> — | K13: =IFERROR(INDEX(#REF!,MATCH(G13,#REF!,0)),"—") -> — | L13: =IF(COUNTIF(L14:L17,"✓ Selesai")=ROWS(L14:L17),"✓ Selesai",IF(COUNTIF(L14:L17,"Terlambat")>0,"Terlambat",IF(COUNTIF(L14:L17,"Revisi")>0,"Revisi","Belum"))) -> ✓ Selesai
A14: ='Kamus WBS'!A10 -> 2.1 | B14: ='Kamus WBS'!B10 -> Identifikasi klien & masalah | C14: ='Kamus WBS'!D10 -> SA | D14: ='Kamus WBS'!E10 -> 3 | E14: — | F14: =IF(OR(E14="",E14="—"),1,INDEX($G$10:$G$45,MATCH(E14,$A$10:$A$45,0))+1) -> 1 | G14: =F14+D14-1 -> 3 | H14: =IFERROR(INDEX(#REF!,MATCH(F14,#REF!,0)),"—") -> — | I14: =IFERROR(INDEX(#REF!,MATCH(G14,#REF!,0)),"—") -> — | J14: =IFERROR(INDEX(#REF!,MATCH(F14,#REF!,0)),"—") -> — | K14: =IFERROR(INDEX(#REF!,MATCH(G14,#REF!,0)),"—") -> — | L14: ✓ Selesai
A15: ='Kamus WBS'!A11 -> 2.2 | B15: ='Kamus WBS'!B11 -> Penentuan tujuan, lingkup & batasan | C15: ='Kamus WBS'!D11 -> SA | D15: ='Kamus WBS'!E11 -> 2 | E15: 2.1 | F15: =IF(OR(E15="",E15="—"),1,INDEX($G$10:$G$45,MATCH(E15,$A$10:$A$45,0))+1) -> 4 | G15: =F15+D15-1 -> 5 | H15: =IFERROR(INDEX(#REF!,MATCH(F15,#REF!,0)),"—") -> — | I15: =IFERROR(INDEX(#REF!,MATCH(G15,#REF!,0)),"—") -> — | J15: =IFERROR(INDEX(#REF!,MATCH(F15,#REF!,0)),"—") -> — | K15: =IFERROR(INDEX(#REF!,MATCH(G15,#REF!,0)),"—") -> — | L15: ✓ Selesai
A16: ='Kamus WBS'!A12 -> 2.3 | B16: ='Kamus WBS'!B12 -> Alternatif solusi & metodologi | C16: ='Kamus WBS'!D12 -> SA | D16: ='Kamus WBS'!E12 -> 3 | E16: 2.2 | F16: =IF(OR(E16="",E16="—"),1,INDEX($G$10:$G$45,MATCH(E16,$A$10:$A$45,0))+1) -> 6 | G16: =F16+D16-1 -> 8 | H16: =IFERROR(INDEX(#REF!,MATCH(F16,#REF!,0)),"—") -> — | I16: =IFERROR(INDEX(#REF!,MATCH(G16,#REF!,0)),"—") -> — | J16: =IFERROR(INDEX(#REF!,MATCH(F16,#REF!,0)),"—") -> — | K16: =IFERROR(INDEX(#REF!,MATCH(G16,#REF!,0)),"—") -> — | L16: ✓ Selesai
A17: ='Kamus WBS'!A13 -> 2.4 | B17: ='Kamus WBS'!B13 -> Penyusunan RD & persetujuan klien | C17: ='Kamus WBS'!D13 -> PM | D17: ='Kamus WBS'!E13 -> 2 | E17: 2.3 | F17: =IF(OR(E17="",E17="—"),1,INDEX($G$10:$G$45,MATCH(E17,$A$10:$A$45,0))+1) -> 9 | G17: =F17+D17-1 -> 10 | H17: =IFERROR(INDEX(#REF!,MATCH(F17,#REF!,0)),"—") -> — | I17: =IFERROR(INDEX(#REF!,MATCH(G17,#REF!,0)),"—") -> — | J17: =IFERROR(INDEX(#REF!,MATCH(F17,#REF!,0)),"—") -> — | K17: =IFERROR(INDEX(#REF!,MATCH(G17,#REF!,0)),"—") -> — | L17: ✓ Selesai
A18: ='Kamus WBS'!A14 -> 3 | B18: ='Kamus WBS'!B14 -> Perencanaan | C18: ='Kamus WBS'!D14 -> PM | D18: =G18-F18+1 -> 10 | E18: 2 | F18: =MIN(F19:F22) -> 11 | G18: =MAX(G19:G22) -> 20 | H18: =IFERROR(INDEX(#REF!,MATCH(F18,#REF!,0)),"—") -> — | I18: =IFERROR(INDEX(#REF!,MATCH(G18,#REF!,0)),"—") -> — | J18: =IFERROR(INDEX(#REF!,MATCH(F18,#REF!,0)),"—") -> — | K18: =IFERROR(INDEX(#REF!,MATCH(G18,#REF!,0)),"—") -> — | L18: =IF(COUNTIF(L19:L22,"✓ Selesai")=ROWS(L19:L22),"✓ Selesai",IF(COUNTIF(L19:L22,"Terlambat")>0,"Terlambat",IF(COUNTIF(L19:L22,"Revisi")>0,"Revisi","Belum"))) -> ✓ Selesai
A19: ='Kamus WBS'!A15 -> 3.1 | B19: ='Kamus WBS'!B15 -> Proses bisnis & gambaran sistem | C19: ='Kamus WBS'!D15 -> SA | D19: ='Kamus WBS'!E15 -> 3 | E19: 2.4 | F19: =IF(OR(E19="",E19="—"),1,INDEX($G$10:$G$45,MATCH(E19,$A$10:$A$45,0))+1) -> 11 | G19: =F19+D19-1 -> 13 | H19: =IFERROR(INDEX(#REF!,MATCH(F19,#REF!,0)),"—") -> — | I19: =IFERROR(INDEX(#REF!,MATCH(G19,#REF!,0)),"—") -> — | J19: =IFERROR(INDEX(#REF!,MATCH(F19,#REF!,0)),"—") -> — | K19: =IFERROR(INDEX(#REF!,MATCH(G19,#REF!,0)),"—") -> — | L19: ✓ Selesai
A20: ='Kamus WBS'!A16 -> 3.2 | B20: ='Kamus WBS'!B16 -> Analisis kelayakan | C20: ='Kamus WBS'!D16 -> SA | D20: ='Kamus WBS'!E16 -> 3 | E20: 3.1 | F20: =IF(OR(E20="",E20="—"),1,INDEX($G$10:$G$45,MATCH(E20,$A$10:$A$45,0))+1) -> 14 | G20: =F20+D20-1 -> 16 | H20: =IFERROR(INDEX(#REF!,MATCH(F20,#REF!,0)),"—") -> — | I20: =IFERROR(INDEX(#REF!,MATCH(G20,#REF!,0)),"—") -> — | J20: =IFERROR(INDEX(#REF!,MATCH(F20,#REF!,0)),"—") -> — | K20: =IFERROR(INDEX(#REF!,MATCH(G20,#REF!,0)),"—") -> — | L20: ✓ Selesai
A21: ='Kamus WBS'!A17 -> 3.3 | B21: ='Kamus WBS'!B17 -> WBS & Gantt Chart | C21: ='Kamus WBS'!D17 -> PM | D21: ='Kamus WBS'!E17 -> 2 | E21: 3.2 | F21: =IF(OR(E21="",E21="—"),1,INDEX($G$10:$G$45,MATCH(E21,$A$10:$A$45,0))+1) -> 17 | G21: =F21+D21-1 -> 18 | H21: =IFERROR(INDEX(#REF!,MATCH(F21,#REF!,0)),"—") -> — | I21: =IFERROR(INDEX(#REF!,MATCH(G21,#REF!,0)),"—") -> — | J21: =IFERROR(INDEX(#REF!,MATCH(F21,#REF!,0)),"—") -> — | K21: =IFERROR(INDEX(#REF!,MATCH(G21,#REF!,0)),"—") -> — | L21: ✓ Selesai
A22: ='Kamus WBS'!A18 -> 3.4 | B22: ='Kamus WBS'!B18 -> Dokumen Bagian II & presentasi | C22: ='Kamus WBS'!D18 -> Tech. Writer | D22: ='Kamus WBS'!E18 -> 2 | E22: 3.3 | F22: =IF(OR(E22="",E22="—"),1,INDEX($G$10:$G$45,MATCH(E22,$A$10:$A$45,0))+1) -> 19 | G22: =F22+D22-1 -> 20 | H22: =IFERROR(INDEX(#REF!,MATCH(F22,#REF!,0)),"—") -> — | I22: =IFERROR(INDEX(#REF!,MATCH(G22,#REF!,0)),"—") -> — | J22: =IFERROR(INDEX(#REF!,MATCH(F22,#REF!,0)),"—") -> — | K22: =IFERROR(INDEX(#REF!,MATCH(G22,#REF!,0)),"—") -> — | L22: ✓ Selesai
A23: ='Kamus WBS'!A19 -> 4 | B23: ='Kamus WBS'!B19 -> Analisis Kebutuhan | C23: ='Kamus WBS'!D19 -> SA | D23: =G23-F23+1 -> 10 | E23: 3 | F23: =MIN(F24:F27) -> 21 | G23: =MAX(G24:G27) -> 30 | H23: =IFERROR(INDEX(#REF!,MATCH(F23,#REF!,0)),"—") -> — | I23: =IFERROR(INDEX(#REF!,MATCH(G23,#REF!,0)),"—") -> — | J23: =IFERROR(INDEX(#REF!,MATCH(F23,#REF!,0)),"—") -> — | K23: =IFERROR(INDEX(#REF!,MATCH(G23,#REF!,0)),"—") -> — | L23: =IF(COUNTIF(L24:L27,"✓ Selesai")=ROWS(L24:L27),"✓ Selesai",IF(COUNTIF(L24:L27,"Terlambat")>0,"Terlambat",IF(COUNTIF(L24:L27,"Revisi")>0,"Revisi","Belum"))) -> Belum
A24: ='Kamus WBS'!A20 -> 4.1 | B24: ='Kamus WBS'!B20 -> Wawancara & observasi lanjutan | C24: ='Kamus WBS'!D20 -> SA | D24: ='Kamus WBS'!E20 -> 2 | E24: 3.4 | F24: =IF(OR(E24="",E24="—"),1,INDEX($G$10:$G$45,MATCH(E24,$A$10:$A$45,0))+1) -> 21 | G24: =F24+D24-1 -> 22 | H24: =IFERROR(INDEX(#REF!,MATCH(F24,#REF!,0)),"—") -> — | I24: =IFERROR(INDEX(#REF!,MATCH(G24,#REF!,0)),"—") -> — | J24: =IFERROR(INDEX(#REF!,MATCH(F24,#REF!,0)),"—") -> — | K24: =IFERROR(INDEX(#REF!,MATCH(G24,#REF!,0)),"—") -> — | L24: ✓ Selesai
A25: ='Kamus WBS'!A21 -> 4.2 | B25: ='Kamus WBS'!B21 -> Kebutuhan fungsional & non-fungsional | C25: ='Kamus WBS'!D21 -> SA | D25: ='Kamus WBS'!E21 -> 3 | E25: 4.1 | F25: =IF(OR(E25="",E25="—"),1,INDEX($G$10:$G$45,MATCH(E25,$A$10:$A$45,0))+1) -> 23 | G25: =F25+D25-1 -> 25 | H25: =IFERROR(INDEX(#REF!,MATCH(F25,#REF!,0)),"—") -> — | I25: =IFERROR(INDEX(#REF!,MATCH(G25,#REF!,0)),"—") -> — | J25: =IFERROR(INDEX(#REF!,MATCH(F25,#REF!,0)),"—") -> — | K25: =IFERROR(INDEX(#REF!,MATCH(G25,#REF!,0)),"—") -> — | L25: ✓ Selesai
A26: ='Kamus WBS'!A22 -> 4.3 | B26: ='Kamus WBS'!B22 -> Prioritas MoSCoW & use case | C26: ='Kamus WBS'!D22 -> SA | D26: ='Kamus WBS'!E22 -> 3 | E26: 4.2 | F26: =IF(OR(E26="",E26="—"),1,INDEX($G$10:$G$45,MATCH(E26,$A$10:$A$45,0))+1) -> 26 | G26: =F26+D26-1 -> 28 | H26: =IFERROR(INDEX(#REF!,MATCH(F26,#REF!,0)),"—") -> — | I26: =IFERROR(INDEX(#REF!,MATCH(G26,#REF!,0)),"—") -> — | J26: =IFERROR(INDEX(#REF!,MATCH(F26,#REF!,0)),"—") -> — | K26: =IFERROR(INDEX(#REF!,MATCH(G26,#REF!,0)),"—") -> — | L26: Belum
A27: ='Kamus WBS'!A23 -> 4.4 | B27: ='Kamus WBS'!B23 -> Penyusunan & review SRS | C27: ='Kamus WBS'!D23 -> Tech. Writer | D27: ='Kamus WBS'!E23 -> 2 | E27: 4.3 | F27: =IF(OR(E27="",E27="—"),1,INDEX($G$10:$G$45,MATCH(E27,$A$10:$A$45,0))+1) -> 29 | G27: =F27+D27-1 -> 30 | H27: =IFERROR(INDEX(#REF!,MATCH(F27,#REF!,0)),"—") -> — | I27: =IFERROR(INDEX(#REF!,MATCH(G27,#REF!,0)),"—") -> — | J27: =IFERROR(INDEX(#REF!,MATCH(F27,#REF!,0)),"—") -> — | K27: =IFERROR(INDEX(#REF!,MATCH(G27,#REF!,0)),"—") -> — | L27: Belum
A28: ='Kamus WBS'!A24 -> 5 | B28: ='Kamus WBS'!B24 -> Desain Sistem | C28: ='Kamus WBS'!D24 -> SD | D28: =G28-F28+1 -> 10 | E28: 4 | F28: =MIN(F29:F32) -> 31 | G28: =MAX(G29:G32) -> 40 | H28: =IFERROR(INDEX(#REF!,MATCH(F28,#REF!,0)),"—") -> — | I28: =IFERROR(INDEX(#REF!,MATCH(G28,#REF!,0)),"—") -> — | J28: =IFERROR(INDEX(#REF!,MATCH(F28,#REF!,0)),"—") -> — | K28: =IFERROR(INDEX(#REF!,MATCH(G28,#REF!,0)),"—") -> — | L28: =IF(COUNTIF(L29:L32,"✓ Selesai")=ROWS(L29:L32),"✓ Selesai",IF(COUNTIF(L29:L32,"Terlambat")>0,"Terlambat",IF(COUNTIF(L29:L32,"Revisi")>0,"Revisi","Belum"))) -> Belum
A29: ='Kamus WBS'!A25 -> 5.1 | B29: ='Kamus WBS'!B25 -> Perancangan basis data (ERD) | C29: ='Kamus WBS'!D25 -> SD | D29: ='Kamus WBS'!E25 -> 3 | E29: 4.4 | F29: =IF(OR(E29="",E29="—"),1,INDEX($G$10:$G$45,MATCH(E29,$A$10:$A$45,0))+1) -> 31 | G29: =F29+D29-1 -> 33 | H29: =IFERROR(INDEX(#REF!,MATCH(F29,#REF!,0)),"—") -> — | I29: =IFERROR(INDEX(#REF!,MATCH(G29,#REF!,0)),"—") -> — | J29: =IFERROR(INDEX(#REF!,MATCH(F29,#REF!,0)),"—") -> — | K29: =IFERROR(INDEX(#REF!,MATCH(G29,#REF!,0)),"—") -> — | L29: Belum
A30: ='Kamus WBS'!A26 -> 5.2 | B30: ='Kamus WBS'!B26 -> Arsitektur sistem & desain modul | C30: ='Kamus WBS'!D26 -> SD | D30: ='Kamus WBS'!E26 -> 2 | E30: 5.1 | F30: =IF(OR(E30="",E30="—"),1,INDEX($G$10:$G$45,MATCH(E30,$A$10:$A$45,0))+1) -> 34 | G30: =F30+D30-1 -> 35 | H30: =IFERROR(INDEX(#REF!,MATCH(F30,#REF!,0)),"—") -> — | I30: =IFERROR(INDEX(#REF!,MATCH(G30,#REF!,0)),"—") -> — | J30: =IFERROR(INDEX(#REF!,MATCH(F30,#REF!,0)),"—") -> — | K30: =IFERROR(INDEX(#REF!,MATCH(G30,#REF!,0)),"—") -> — | L30: Belum
A31: ='Kamus WBS'!A27 -> 5.3 | B31: ='Kamus WBS'!B27 -> Desain antarmuka (wireframe) | C31: ='Kamus WBS'!D27 -> SD | D31: ='Kamus WBS'!E27 -> 3 | E31: 5.2 | F31: =IF(OR(E31="",E31="—"),1,INDEX($G$10:$G$45,MATCH(E31,$A$10:$A$45,0))+1) -> 36 | G31: =F31+D31-1 -> 38 | H31: =IFERROR(INDEX(#REF!,MATCH(F31,#REF!,0)),"—") -> — | I31: =IFERROR(INDEX(#REF!,MATCH(G31,#REF!,0)),"—") -> — | J31: =IFERROR(INDEX(#REF!,MATCH(F31,#REF!,0)),"—") -> — | K31: =IFERROR(INDEX(#REF!,MATCH(G31,#REF!,0)),"—") -> — | L31: Belum
A32: ='Kamus WBS'!A28 -> 5.4 | B32: ='Kamus WBS'!B28 -> Penyusunan SDD | C32: ='Kamus WBS'!D28 -> SD | D32: ='Kamus WBS'!E28 -> 2 | E32: 5.3 | F32: =IF(OR(E32="",E32="—"),1,INDEX($G$10:$G$45,MATCH(E32,$A$10:$A$45,0))+1) -> 39 | G32: =F32+D32-1 -> 40 | H32: =IFERROR(INDEX(#REF!,MATCH(F32,#REF!,0)),"—") -> — | I32: =IFERROR(INDEX(#REF!,MATCH(G32,#REF!,0)),"—") -> — | J32: =IFERROR(INDEX(#REF!,MATCH(F32,#REF!,0)),"—") -> — | K32: =IFERROR(INDEX(#REF!,MATCH(G32,#REF!,0)),"—") -> — | L32: Belum
A33: ='Kamus WBS'!A29 -> 6 | B33: ='Kamus WBS'!B29 -> Pemrograman | C33: ='Kamus WBS'!D29 -> Programmer | D33: =G33-F33+1 -> 15 | E33: 5 | F33: =MIN(F34:F36) -> 41 | G33: =MAX(G34:G36) -> 55 | H33: =IFERROR(INDEX(#REF!,MATCH(F33,#REF!,0)),"—") -> — | I33: =IFERROR(INDEX(#REF!,MATCH(G33,#REF!,0)),"—") -> — | J33: =IFERROR(INDEX(#REF!,MATCH(F33,#REF!,0)),"—") -> — | K33: =IFERROR(INDEX(#REF!,MATCH(G33,#REF!,0)),"—") -> — | L33: =IF(COUNTIF(L34:L36,"✓ Selesai")=ROWS(L34:L36),"✓ Selesai",IF(COUNTIF(L34:L36,"Terlambat")>0,"Terlambat",IF(COUNTIF(L34:L36,"Revisi")>0,"Revisi","Belum"))) -> Belum
A34: ='Kamus WBS'!A30 -> 6.1 | B34: ='Kamus WBS'!B30 -> Sprint 1 – fitur dasar | C34: ='Kamus WBS'!D30 -> Programmer | D34: ='Kamus WBS'!E30 -> 5 | E34: 5.4 | F34: =IF(OR(E34="",E34="—"),1,INDEX($G$10:$G$45,MATCH(E34,$A$10:$A$45,0))+1) -> 41 | G34: =F34+D34-1 -> 45 | H34: =IFERROR(INDEX(#REF!,MATCH(F34,#REF!,0)),"—") -> — | I34: =IFERROR(INDEX(#REF!,MATCH(G34,#REF!,0)),"—") -> — | J34: =IFERROR(INDEX(#REF!,MATCH(F34,#REF!,0)),"—") -> — | K34: =IFERROR(INDEX(#REF!,MATCH(G34,#REF!,0)),"—") -> — | L34: Belum
A35: ='Kamus WBS'!A31 -> 6.2 | B35: ='Kamus WBS'!B31 -> Sprint 2 – fitur lanjutan | C35: ='Kamus WBS'!D31 -> Programmer | D35: ='Kamus WBS'!E31 -> 5 | E35: 6.1 | F35: =IF(OR(E35="",E35="—"),1,INDEX($G$10:$G$45,MATCH(E35,$A$10:$A$45,0))+1) -> 46 | G35: =F35+D35-1 -> 50 | H35: =IFERROR(INDEX(#REF!,MATCH(F35,#REF!,0)),"—") -> — | I35: =IFERROR(INDEX(#REF!,MATCH(G35,#REF!,0)),"—") -> — | J35: =IFERROR(INDEX(#REF!,MATCH(F35,#REF!,0)),"—") -> — | K35: =IFERROR(INDEX(#REF!,MATCH(G35,#REF!,0)),"—") -> — | L35: Belum
A36: ='Kamus WBS'!A32 -> 6.3 | B36: ='Kamus WBS'!B32 -> Sprint 3 – semua fitur lengkap | C36: ='Kamus WBS'!D32 -> Programmer | D36: ='Kamus WBS'!E32 -> 5 | E36: 6.2 | F36: =IF(OR(E36="",E36="—"),1,INDEX($G$10:$G$45,MATCH(E36,$A$10:$A$45,0))+1) -> 51 | G36: =F36+D36-1 -> 55 | H36: =IFERROR(INDEX(#REF!,MATCH(F36,#REF!,0)),"—") -> — | I36: =IFERROR(INDEX(#REF!,MATCH(G36,#REF!,0)),"—") -> — | J36: =IFERROR(INDEX(#REF!,MATCH(F36,#REF!,0)),"—") -> — | K36: =IFERROR(INDEX(#REF!,MATCH(G36,#REF!,0)),"—") -> — | L36: Belum
A37: ='Kamus WBS'!A33 -> 7 | B37: ='Kamus WBS'!B33 -> Pengujian | C37: ='Kamus WBS'!D33 -> Tester | D37: =G37-F37+1 -> 5 | E37: 6 | F37: =MIN(F38:F40) -> 56 | G37: =MAX(G38:G40) -> 60 | H37: =IFERROR(INDEX(#REF!,MATCH(F37,#REF!,0)),"—") -> — | I37: =IFERROR(INDEX(#REF!,MATCH(G37,#REF!,0)),"—") -> — | J37: =IFERROR(INDEX(#REF!,MATCH(F37,#REF!,0)),"—") -> — | K37: =IFERROR(INDEX(#REF!,MATCH(G37,#REF!,0)),"—") -> — | L37: =IF(COUNTIF(L38:L40,"✓ Selesai")=ROWS(L38:L40),"✓ Selesai",IF(COUNTIF(L38:L40,"Terlambat")>0,"Terlambat",IF(COUNTIF(L38:L40,"Revisi")>0,"Revisi","Belum"))) -> Belum
A38: ='Kamus WBS'!A34 -> 7.1 | B38: ='Kamus WBS'!B34 -> Pengujian modul & integrasi | C38: ='Kamus WBS'!D34 -> Tester | D38: ='Kamus WBS'!E34 -> 2 | E38: 6.3 | F38: =IF(OR(E38="",E38="—"),1,INDEX($G$10:$G$45,MATCH(E38,$A$10:$A$45,0))+1) -> 56 | G38: =F38+D38-1 -> 57 | H38: =IFERROR(INDEX(#REF!,MATCH(F38,#REF!,0)),"—") -> — | I38: =IFERROR(INDEX(#REF!,MATCH(G38,#REF!,0)),"—") -> — | J38: =IFERROR(INDEX(#REF!,MATCH(F38,#REF!,0)),"—") -> — | K38: =IFERROR(INDEX(#REF!,MATCH(G38,#REF!,0)),"—") -> — | L38: Belum
A39: ='Kamus WBS'!A35 -> 7.2 | B39: ='Kamus WBS'!B35 -> User Acceptance Test (UAT) | C39: ='Kamus WBS'!D35 -> Tester | D39: ='Kamus WBS'!E35 -> 2 | E39: 7.1 | F39: =IF(OR(E39="",E39="—"),1,INDEX($G$10:$G$45,MATCH(E39,$A$10:$A$45,0))+1) -> 58 | G39: =F39+D39-1 -> 59 | H39: =IFERROR(INDEX(#REF!,MATCH(F39,#REF!,0)),"—") -> — | I39: =IFERROR(INDEX(#REF!,MATCH(G39,#REF!,0)),"—") -> — | J39: =IFERROR(INDEX(#REF!,MATCH(F39,#REF!,0)),"—") -> — | K39: =IFERROR(INDEX(#REF!,MATCH(G39,#REF!,0)),"—") -> — | L39: Belum
A40: ='Kamus WBS'!A36 -> 7.3 | B40: ='Kamus WBS'!B36 -> Perbaikan bug & uji ulang | C40: ='Kamus WBS'!D36 -> Programmer | D40: ='Kamus WBS'!E36 -> 1 | E40: 7.2 | F40: =IF(OR(E40="",E40="—"),1,INDEX($G$10:$G$45,MATCH(E40,$A$10:$A$45,0))+1) -> 60 | G40: =F40+D40-1 -> 60 | H40: =IFERROR(INDEX(#REF!,MATCH(F40,#REF!,0)),"—") -> — | I40: =IFERROR(INDEX(#REF!,MATCH(G40,#REF!,0)),"—") -> — | J40: =IFERROR(INDEX(#REF!,MATCH(F40,#REF!,0)),"—") -> — | K40: =IFERROR(INDEX(#REF!,MATCH(G40,#REF!,0)),"—") -> — | L40: Belum
...
